<?xml version="1.0" ?>
<!-- =================================================================================== -->
<!-- |    This document was autogenerated by xacro from hexapod_model.xacro            | -->
<!-- |    EDITING THIS FILE BY HAND IS NOT RECOMMENDED                                 | -->
<!-- =================================================================================== -->
<robot name="hexapod" xmlns:xacro="http://ros.org/wiki/xacro">
  <!-- Build the base of the body -->
  <link name="base_link"/>
  <joint name="base_joint" type="fixed">
    <parent link="base_link"/>
    <child link="thorax"/>
    <origin rpy="0 0 0" xyz="0 0 0"/>
  </joint>
  <link name="thorax">
    <visual>
      <origin rpy="0 0 0" xyz="0 0 0"/>
      <geometry>
        <mesh filename="package://hexapod_description_pkg/meshes/thorax.STL"/>
      </geometry>
      <material name="grey">
        <color rgba="0.5 0.5 0.5 1"/>
      </material>
    </visual>
  </link>
  <!-- Leg Building Code -->
  <!-- Fixed link -->
  <joint name="leg_center_joint_r1" type="fixed">
    <origin rpy="0 0 0" xyz="0.087598 -0.050575 0"/>
    <parent link="thorax"/>
    <child link="leg_center_r1"/>
  </joint>
  <link name="leg_center_r1"/>
  <!-- First Motor -->
  <joint name="coxa_joint_r1" type="revolute">
    <origin rpy="0 0 -1.0471975512" xyz="0 0 0"/>
    <parent link="leg_center_r1"/>
    <child link="coxa_r1"/>
    <axis xyz="0 0 -1"/>
    <limit effort="10000" lower="-1.5" upper="1.5" velocity="100"/>
  </joint>
  <link name="coxa_r1">
    <visual>
      <origin rpy="0 0 0" xyz="0 0 0"/>
      <geometry>
        <mesh filename="package://hexapod_description_pkg/meshes/coxa_r.STL"/>
      </geometry>
      <material name="">
        <color rgba="0.7 0.7 0 1"/>
      </material>
    </visual>
  </link>
  <!-- First Scheletal Part -->
  <joint name="femur_joint_r1" type="revolute">
    <origin rpy="-1.57079632679 0 0" xyz="0.0294 0 0"/>
    <parent link="coxa_r1"/>
    <child link="femur_r1"/>
    <axis xyz="0 0 -1"/>
    <limit effort="10000" lower="-1.5" upper="1.5" velocity="100"/>
  </joint>
  <link name="femur_r1">
    <visual>
      <origin rpy="0 0 0" xyz="0 0 0"/>
      <geometry>
        <mesh filename="package://hexapod_description_pkg/meshes/femur_r.STL"/>
      </geometry>
      <material name="">
        <color rgba="0 0.7 0.7 1"/>
      </material>
    </visual>
  </link>
  <!-- Second Scheletal Part -->
  <joint name="tibia_joint_r1" type="revolute">
    <origin rpy="3.14159265359 0 1.57079632679" xyz="0.08 0 0"/>
    <parent link="femur_r1"/>
    <child link="tibia_r1"/>
    <axis xyz="0 0 1"/>
    <limit effort="10000" lower="-1.5" upper="1.5" velocity="100"/>
  </joint>
  <link name="tibia_r1">
    <visual>
      <origin rpy="0 0 0.06" xyz="0 0 0"/>
      <geometry>
        <mesh filename="package://hexapod_description_pkg/meshes/tibia_l.STL"/>
      </geometry>
      <material name="">
        <color rgba="0.7 0 0.7 1"/>
      </material>
    </visual>
  </link>
  <!-- Foot Part -->
  <joint name="tibia_foot_joint_r1" type="fixed">
    <origin rpy="0 0 0" xyz="0.117 0 0"/>
    <parent link="tibia_r1"/>
    <child link="tibia_foot_r1"/>
  </joint>
  <link name="tibia_foot_r1"/>
  <!-- Leg Building Code -->
  <!-- Fixed link -->
  <joint name="leg_center_joint_r2" type="fixed">
    <origin rpy="0 0 0" xyz="0 -0.06985 0"/>
    <parent link="thorax"/>
    <child link="leg_center_r2"/>
  </joint>
  <link name="leg_center_r2"/>
  <!-- First Motor -->
  <joint name="coxa_joint_r2" type="revolute">
    <origin rpy="0 0 -1.57079632679" xyz="0 0 0"/>
    <parent link="leg_center_r2"/>
    <child link="coxa_r2"/>
    <axis xyz="0 0 -1"/>
    <limit effort="10000" lower="-1.5" upper="1.5" velocity="100"/>
  </joint>
  <link name="coxa_r2">
    <visual>
      <origin rpy="0 0 0" xyz="0 0 0"/>
      <geometry>
        <mesh filename="package://hexapod_description_pkg/meshes/coxa_r.STL"/>
      </geometry>
      <material name="">
        <color rgba="0.7 0.7 0 1"/>
      </material>
    </visual>
  </link>
  <!-- First Scheletal Part -->
  <joint name="femur_joint_r2" type="revolute">
    <origin rpy="-1.57079632679 0 0" xyz="0.0294 0 0"/>
    <parent link="coxa_r2"/>
    <child link="femur_r2"/>
    <axis xyz="0 0 -1"/>
    <limit effort="10000" lower="-1.5" upper="1.5" velocity="100"/>
  </joint>
  <link name="femur_r2">
    <visual>
      <origin rpy="0 0 0" xyz="0 0 0"/>
      <geometry>
        <mesh filename="package://hexapod_description_pkg/meshes/femur_r.STL"/>
      </geometry>
      <material name="">
        <color rgba="0 0.7 0.7 1"/>
      </material>
    </visual>
  </link>
  <!-- Second Scheletal Part -->
  <joint name="tibia_joint_r2" type="revolute">
    <origin rpy="3.14159265359 0 1.57079632679" xyz="0.08 0 0"/>
    <parent link="femur_r2"/>
    <child link="tibia_r2"/>
    <axis xyz="0 0 1"/>
    <limit effort="10000" lower="-1.5" upper="1.5" velocity="100"/>
  </joint>
  <link name="tibia_r2">
    <visual>
      <origin rpy="0 0 0.06" xyz="0 0 0"/>
      <geometry>
        <mesh filename="package://hexapod_description_pkg/meshes/tibia_l.STL"/>
      </geometry>
      <material name="">
        <color rgba="0.7 0 0.7 1"/>
      </material>
    </visual>
  </link>
  <!-- Foot Part -->
  <joint name="tibia_foot_joint_r2" type="fixed">
    <origin rpy="0 0 0" xyz="0.117 0 0"/>
    <parent link="tibia_r2"/>
    <child link="tibia_foot_r2"/>
  </joint>
  <link name="tibia_foot_r2"/>
  <!-- Leg Building Code -->
  <!-- Fixed link -->
  <joint name="leg_center_joint_r3" type="fixed">
    <origin rpy="0 0 0" xyz="-0.087598 -0.050575 0"/>
    <parent link="thorax"/>
    <child link="leg_center_r3"/>
  </joint>
  <link name="leg_center_r3"/>
  <!-- First Motor -->
  <joint name="coxa_joint_r3" type="revolute">
    <origin rpy="0 0 -2.09439510239" xyz="0 0 0"/>
    <parent link="leg_center_r3"/>
    <child link="coxa_r3"/>
    <axis xyz="0 0 -1"/>
    <limit effort="10000" lower="-1.5" upper="1.5" velocity="100"/>
  </joint>
  <link name="coxa_r3">
    <visual>
      <origin rpy="0 0 0" xyz="0 0 0"/>
      <geometry>
        <mesh filename="package://hexapod_description_pkg/meshes/coxa_r.STL"/>
      </geometry>
      <material name="">
        <color rgba="0.7 0.7 0 1"/>
      </material>
    </visual>
  </link>
  <!-- First Scheletal Part -->
  <joint name="femur_joint_r3" type="revolute">
    <origin rpy="-1.57079632679 0 0" xyz="0.0294 0 0"/>
    <parent link="coxa_r3"/>
    <child link="femur_r3"/>
    <axis xyz="0 0 -1"/>
    <limit effort="10000" lower="-1.5" upper="1.5" velocity="100"/>
  </joint>
  <link name="femur_r3">
    <visual>
      <origin rpy="0 0 0" xyz="0 0 0"/>
      <geometry>
        <mesh filename="package://hexapod_description_pkg/meshes/femur_r.STL"/>
      </geometry>
      <material name="">
        <color rgba="0 0.7 0.7 1"/>
      </material>
    </visual>
  </link>
  <!-- Second Scheletal Part -->
  <joint name="tibia_joint_r3" type="revolute">
    <origin rpy="3.14159265359 0 1.57079632679" xyz="0.08 0 0"/>
    <parent link="femur_r3"/>
    <child link="tibia_r3"/>
    <axis xyz="0 0 1"/>
    <limit effort="10000" lower="-1.5" upper="1.5" velocity="100"/>
  </joint>
  <link name="tibia_r3">
    <visual>
      <origin rpy="0 0 0.06" xyz="0 0 0"/>
      <geometry>
        <mesh filename="package://hexapod_description_pkg/meshes/tibia_l.STL"/>
      </geometry>
      <material name="">
        <color rgba="0.7 0 0.7 1"/>
      </material>
    </visual>
  </link>
  <!-- Foot Part -->
  <joint name="tibia_foot_joint_r3" type="fixed">
    <origin rpy="0 0 0" xyz="0.117 0 0"/>
    <parent link="tibia_r3"/>
    <child link="tibia_foot_r3"/>
  </joint>
  <link name="tibia_foot_r3"/>
  <!-- Leg Building Code -->
  <!-- Fixed link -->
  <joint name="leg_center_joint_l1" type="fixed">
    <origin rpy="0 0 0" xyz="0.087598 0.050575 0"/>
    <parent link="thorax"/>
    <child link="leg_center_l1"/>
  </joint>
  <link name="leg_center_l1"/>
  <!-- First Motor -->
  <joint name="coxa_joint_l1" type="revolute">
    <origin rpy="0 0 1.0471975512" xyz="0 0 0"/>
    <parent link="leg_center_l1"/>
    <child link="coxa_l1"/>
    <axis xyz="0 0 -1"/>
    <limit effort="10000" lower="-1.5" upper="1.5" velocity="100"/>
  </joint>
  <link name="coxa_l1">
    <visual>
      <origin rpy="0 0 0" xyz="0 0 0"/>
      <geometry>
        <mesh filename="package://hexapod_description_pkg/meshes/coxa_l.STL"/>
      </geometry>
      <material name="">
        <color rgba="0.7 0.7 0 1"/>
      </material>
    </visual>
  </link>
  <!-- First Scheletal Part -->
  <joint name="femur_joint_l1" type="revolute">
    <origin rpy="-1.57079632679 0 0" xyz="0.0294 0 0"/>
    <parent link="coxa_l1"/>
    <child link="femur_l1"/>
    <axis xyz="0 0 -1"/>
    <limit effort="10000" lower="-1.5" upper="1.5" velocity="100"/>
  </joint>
  <link name="femur_l1">
    <visual>
      <origin rpy="0 0 0" xyz="0 0 0"/>
      <geometry>
        <mesh filename="package://hexapod_description_pkg/meshes/femur_l.STL"/>
      </geometry>
      <material name="">
        <color rgba="0 0.7 0.7 1"/>
      </material>
    </visual>
  </link>
  <!-- Second Scheletal Part -->
  <joint name="tibia_joint_l1" type="revolute">
    <origin rpy="3.14159265359 0 1.57079632679" xyz="0.08 0 0"/>
    <parent link="femur_l1"/>
    <child link="tibia_l1"/>
    <axis xyz="0 0 1"/>
    <limit effort="10000" lower="-1.5" upper="1.5" velocity="100"/>
  </joint>
  <link name="tibia_l1">
    <visual>
      <origin rpy="0 0 0.06" xyz="0 0 0"/>
      <geometry>
        <mesh filename="package://hexapod_description_pkg/meshes/tibia_l.STL"/>
      </geometry>
      <material name="">
        <color rgba="0.7 0 0.7 1"/>
      </material>
    </visual>
  </link>
  <!-- Foot Part -->
  <joint name="tibia_foot_joint_l1" type="fixed">
    <origin rpy="0 0 0" xyz="0.117 0 0"/>
    <parent link="tibia_l1"/>
    <child link="tibia_foot_l1"/>
  </joint>
  <link name="tibia_foot_l1"/>
  <!-- Leg Building Code -->
  <!-- Fixed link -->
  <joint name="leg_center_joint_l2" type="fixed">
    <origin rpy="0 0 0" xyz="0 0.06985 0"/>
    <parent link="thorax"/>
    <child link="leg_center_l2"/>
  </joint>
  <link name="leg_center_l2"/>
  <!-- First Motor -->
  <joint name="coxa_joint_l2" type="revolute">
    <origin rpy="0 0 1.57079632679" xyz="0 0 0"/>
    <parent link="leg_center_l2"/>
    <child link="coxa_l2"/>
    <axis xyz="0 0 -1"/>
    <limit effort="10000" lower="-1.5" upper="1.5" velocity="100"/>
  </joint>
  <link name="coxa_l2">
    <visual>
      <origin rpy="0 0 0" xyz="0 0 0"/>
      <geometry>
        <mesh filename="package://hexapod_description_pkg/meshes/coxa_l.STL"/>
      </geometry>
      <material name="">
        <color rgba="0.7 0.7 0 1"/>
      </material>
    </visual>
  </link>
  <!-- First Scheletal Part -->
  <joint name="femur_joint_l2" type="revolute">
    <origin rpy="-1.57079632679 0 0" xyz="0.0294 0 0"/>
    <parent link="coxa_l2"/>
    <child link="femur_l2"/>
    <axis xyz="0 0 -1"/>
    <limit effort="10000" lower="-1.5" upper="1.5" velocity="100"/>
  </joint>
  <link name="femur_l2">
    <visual>
      <origin rpy="0 0 0" xyz="0 0 0"/>
      <geometry>
        <mesh filename="package://hexapod_description_pkg/meshes/femur_l.STL"/>
      </geometry>
      <material name="">
        <color rgba="0 0.7 0.7 1"/>
      </material>
    </visual>
  </link>
  <!-- Second Scheletal Part -->
  <joint name="tibia_joint_l2" type="revolute">
    <origin rpy="3.14159265359 0 1.57079632679" xyz="0.08 0 0"/>
    <parent link="femur_l2"/>
    <child link="tibia_l2"/>
    <axis xyz="0 0 1"/>
    <limit effort="10000" lower="-1.5" upper="1.5" velocity="100"/>
  </joint>
  <link name="tibia_l2">
    <visual>
      <origin rpy="0 0 0.06" xyz="0 0 0"/>
      <geometry>
        <mesh filename="package://hexapod_description_pkg/meshes/tibia_l.STL"/>
      </geometry>
      <material name="">
        <color rgba="0.7 0 0.7 1"/>
      </material>
    </visual>
  </link>
  <!-- Foot Part -->
  <joint name="tibia_foot_joint_l2" type="fixed">
    <origin rpy="0 0 0" xyz="0.117 0 0"/>
    <parent link="tibia_l2"/>
    <child link="tibia_foot_l2"/>
  </joint>
  <link name="tibia_foot_l2"/>
  <!-- Leg Building Code -->
  <!-- Fixed link -->
  <joint name="leg_center_joint_l3" type="fixed">
    <origin rpy="0 0 0" xyz="-0.087598 0.050575 0"/>
    <parent link="thorax"/>
    <child link="leg_center_l3"/>
  </joint>
  <link name="leg_center_l3"/>
  <!-- First Motor -->
  <joint name="coxa_joint_l3" type="revolute">
    <origin rpy="0 0 2.09439510239" xyz="0 0 0"/>
    <parent link="leg_center_l3"/>
    <child link="coxa_l3"/>
    <axis xyz="0 0 -1"/>
    <limit effort="10000" lower="-1.5" upper="1.5" velocity="100"/>
  </joint>
  <link name="coxa_l3">
    <visual>
      <origin rpy="0 0 0" xyz="0 0 0"/>
      <geometry>
        <mesh filename="package://hexapod_description_pkg/meshes/coxa_l.STL"/>
      </geometry>
      <material name="">
        <color rgba="0.7 0.7 0 1"/>
      </material>
    </visual>
  </link>
  <!-- First Scheletal Part -->
  <joint name="femur_joint_l3" type="revolute">
    <origin rpy="-1.57079632679 0 0" xyz="0.0294 0 0"/>
    <parent link="coxa_l3"/>
    <child link="femur_l3"/>
    <axis xyz="0 0 -1"/>
    <limit effort="10000" lower="-1.5" upper="1.5" velocity="100"/>
  </joint>
  <link name="femur_l3">
    <visual>
      <origin rpy="0 0 0" xyz="0 0 0"/>
      <geometry>
        <mesh filename="package://hexapod_description_pkg/meshes/femur_l.STL"/>
      </geometry>
      <material name="">
        <color rgba="0 0.7 0.7 1"/>
      </material>
    </visual>
  </link>
  <!-- Second Scheletal Part -->
  <joint name="tibia_joint_l3" type="revolute">
    <origin rpy="3.14159265359 0 1.57079632679" xyz="0.08 0 0"/>
    <parent link="femur_l3"/>
    <child link="tibia_l3"/>
    <axis xyz="0 0 1"/>
    <limit effort="10000" lower="-1.5" upper="1.5" velocity="100"/>
  </joint>
  <link name="tibia_l3">
    <visual>
      <origin rpy="0 0 0.06" xyz="0 0 0"/>
      <geometry>
        <mesh filename="package://hexapod_description_pkg/meshes/tibia_l.STL"/>
      </geometry>
      <material name="">
        <color rgba="0.7 0 0.7 1"/>
      </material>
    </visual>
  </link>
  <!-- Foot Part -->
  <joint name="tibia_foot_joint_l3" type="fixed">
    <origin rpy="0 0 0" xyz="0.117 0 0"/>
    <parent link="tibia_l3"/>
    <child link="tibia_foot_l3"/>
  </joint>
  <link name="tibia_foot_l3"/>
</robot>

